Workbook

Sheet Rules
A1: Ride rules, replayed on every offer this month
A2: Each rule sits on top of what you did: it drops the rides you took that it would have skipped, then fills the freed time with offers you passed on that fit. True profit is after electricity, wear on the car and tires.
A4: Rule | B4: Rides | C4: True profit ($) | D4: Per hour on the road ($) | E4: Versus what you did ($) | F4: Rides you took that it skips | G4: Offers you passed that it takes
A5: What you did | B5: =COUNTIF(Offers!$J$2:$J$239,"Took") | C5: =SUMIFS(Offers!$M$2:$M$239,Offers!$J$2:$J$239,"Took") | D5: =C5/Assumptions!$B$15 | E5: =C5-$C$5 | F5: 0 | G5: 0
A6: Skip pickups over 3 miles | B6: =COUNTIF(Offers!$N$2:$N$239,"Take") | C6: =SUMIFS(Offers!$M$2:$M$239,Offers!$N$2:$N$239,"Take") | D6: =C6/Assumptions!$B$15 | E6: =C6-$C$5 | F6: =COUNTIFS(Offers!$J$2:$J$239,"Took",Offers!$N$2:$N$239,"<>Take") | G6: =COUNTIFS(Offers!$J$2:$J$239,"Passed",Offers!$N$2:$N$239,"Take")
A7: Skip pickups over 2 miles | B7: =COUNTIF(Offers!$O$2:$O$239,"Take") | C7: =SUMIFS(Offers!$M$2:$M$239,Offers!$O$2:$O$239,"Take") | D7: =C7/Assumptions!$B$15 | E7: =C7-$C$5 | F7: =COUNTIFS(Offers!$J$2:$J$239,"Took",Offers!$O$2:$O$239,"<>Take") | G7: =COUNTIFS(Offers!$J$2:$J$239,"Passed",Offers!$O$2:$O$239,"Take")
A8: At least $1 a mile | B8: =COUNTIF(Offers!$P$2:$P$239,"Take") | C8: =SUMIFS(Offers!$M$2:$M$239,Offers!$P$2:$P$239,"Take") | D8: =C8/Assumptions!$B$15 | E8: =C8-$C$5 | F8: =COUNTIFS(Offers!$J$2:$J$239,"Took",Offers!$P$2:$P$239,"<>Take") | G8: =COUNTIFS(Offers!$J$2:$J$239,"Passed",Offers!$P$2:$P$239,"Take")
A9: At least $20 an hour after car costs | B9: =COUNTIF(Offers!$Q$2:$Q$239,"Take") | C9: =SUMIFS(Offers!$M$2:$M$239,Offers!$Q$2:$Q$239,"Take") | D9: =C9/Assumptions!$B$15 | E9: =C9-$C$5 | F9: =COUNTIFS(Offers!$J$2:$J$239,"Took",Offers!$Q$2:$Q$239,"<>Take") | G9: =COUNTIFS(Offers!$J$2:$J$239,"Passed",Offers!$Q$2:$Q$239,"Take")
A10: Take every offer | B10: =COUNTIF(Offers!$R$2:$R$239,"Take") | C10: =SUMIFS(Offers!$M$2:$M$239,Offers!$R$2:$R$239,"Take") | D10: =C10/Assumptions!$B$15 | E10: =C10-$C$5 | F10: =COUNTIFS(Offers!$J$2:$J$239,"Took",Offers!$R$2:$R$239,"<>Take") | G10: =COUNTIFS(Offers!$J$2:$J$239,"Passed",Offers!$R$2:$R$239,"Take")
A12: Rides driven keep their real fare, tip, time and costs. Offers passed on are estimated from their offer cards (see Assumptions).
A13: Hours on the road are the same for every rule, so the per-hour column compares rules fairly.
A14: Say a rule in the app ("What if I skip pickups over 4 miles?") to replay one that isn't listed here.

Sheet Assumptions
A1: Assumptions behind the estimates
A3: Input | B3: Value | C3: Where it comes from
A4: Electricity used per mile (kWh) | B4: 0.24970725 | C4: Tessie drives for the month: energy used over miles driven
A5: Home electricity ($/kWh) | B5: 0.14 | C5: Owner's vehicle profile
A6: Supercharger ($/kWh) | B6: 0.42 | C6: Owner's vehicle profile
A7: Share of charging at Superchargers | B7: 0.25 | C7: Owner's vehicle profile
A8: Blended electricity ($/kWh) | B8: =B5*(1-B7)+B6*B7 | C8: Home and Supercharger rates, weighted by share
A9: Wear on the car ($/mile) | B9: 0.2 | C9: Owner's vehicle profile (depreciation)
A10: Tire set ($) | B10: 1100 | C10: Owner's vehicle profile
A11: Tire life (miles) | B11: 40000 | C11: Owner's vehicle profile
A12: Tire wear ($/mile) | B12: =B10/B11 | C12: Tire set over tire life
A13: Car cost per mile ($) | B13: =B4*B8+B9+B12 | C13: Electricity plus wear plus tires
A14: Tip rate on rides driven | B14: 0.076142969 | C14: Rides driven this month: tips as a share of the fares on their offer cards
A15: Hours on the road | B15: 112.88972 | C15: Real offers and rides, in stretches; a gap over 30 minutes counts as off
A16: Queue window (minutes) | B16: 20 | C16: A passed-on offer counts only if the car is free within this long
A18: Blue values are inputs you can change. Changing them updates the estimated profit of offers that were passed on, and every total on the Rules tab.
A19: Which offers each rule takes (Take, Skip, Busy on the Offers tab) comes from the replay in car/rules.py and does not change when you edit these inputs.
A20: Synthetic data for a fictional operator, Bayou City Mobility LLC. Advice only: no app accepts or declines rides for you.

Sheet Offers
A1: Offered | B1: Platform | C1: Pickup (mi) | D1: Pickup (min) | E1: Trip (mi) | F1: Trip (min) | G1: Fare on card ($) | H1: Fare per mile ($) | I1: Card $/hr after car costs | J1: You | K1: Fare + tip, actual ($) | L1: True profit, actual ($) | M1: True profit used ($) | N1: Skip pickups over 3 miles | O1: Skip pickups over 2 miles | P1: At least $1 a mile | Q1: At least $20 an hour after car costs | R1: Take every offer | S1: Offer ID
A2: 46296.404 | B2: Uber | C2: 1.79 | D2: 6.7 | E2: 16.72 | F2: 44 | G2: 30.12 | H2: =IFERROR(G2/(C2+E2),0) | I2: =IFERROR((G2-(C2+E2)*Assumptions!$B$13)/((D2+F2)/60),0) | J2: Passed | M2: =IF(J2="Took",L2,ROUND(G2*(1+Assumptions!$B$14)-(C2+E2)*Assumptions!$B$13,2)) | N2: Busy | O2: Take | P2: Busy | Q2: Busy | R2: Busy | S2: f74c76
A3: 46296.406 | B3: Uber | C3: 2.27 | D3: 8.6 | E3: 9.52 | F3: 27.1 | G3: 17.12 | H3: =IFERROR(G3/(C3+E3),0) | I3: =IFERROR((G3-(C3+E3)*Assumptions!$B$13)/((D3+F3)/60),0) | J3: Took | K3: 27.98 | L3: 24.67 | M3: =IF(J3="Took",L3,ROUND(G3*(1+Assumptions!$B$14)-(C3+E3)*Assumptions!$B$13,2)) | N3: Take | O3: Skip | P3: Take | Q3: Take | R3: Take | S3: 88ca7f
A4: 46296.5 | B4: Lyft | C4: 4.44 | D4: 13.6 | E4: 7.06 | F4: 22.4 | G4: 16.2 | H4: =IFERROR(G4/(C4+E4),0) | I4: =IFERROR((G4-(C4+E4)*Assumptions!$B$13)/((D4+F4)/60),0) | J4: Passed | M4: =IF(J4="Took",L4,ROUND(G4*(1+Assumptions!$B$14)-(C4+E4)*Assumptions!$B$13,2)) | N4: Skip | O4: Skip | P4: Busy | Q4: Busy | R4: Busy | S4: d7b99d
A5: 46296.508 | B5: Lyft | C5: 1.35 | D5: 5.8 | E5: 12.07 | F5: 30.6 | G5: 41.66 | H5: =IFERROR(G5/(C5+E5),0) | I5: =IFERROR((G5-(C5+E5)*Assumptions!$B$13)/((D5+F5)/60),0) | J5: Took | K5: 41.66 | L5: 37.92 | M5: =IF(J5="Took",L5,ROUND(G5*(1+Assumptions!$B$14)-(C5+E5)*Assumptions!$B$13,2)) | N5: Take | O5: Take | P5: Take | Q5: Take | R5: Take | S5: baf4b8
A6: 46296.595 | B6: Uber | C6: 1.25 | D6: 5.3 | E6: 21.85 | F6: 52.1 | G6: 39.51 | H6: =IFERROR(G6/(C6+E6),0) | I6: =IFERROR((G6-(C6+E6)*Assumptions!$B$13)/((D6+F6)/60),0) | J6: Passed | M6: =IF(J6="Took",L6,ROUND(G6*(1+Assumptions!$B$14)-(C6+E6)*Assumptions!$B$13,2)) | N6: Busy | O6: Busy | P6: Busy | Q6: Busy | R6: Busy | S6: d6a95d
A7: 46296.607 | B7: Uber | C7: 0.74 | D7: 3.6 | E7: 11.66 | F7: 31.5 | G7: 20.58 | H7: =IFERROR(G7/(C7+E7),0) | I7: =IFERROR((G7-(C7+E7)*Assumptions!$B$13)/((D7+F7)/60),0) | J7: Took | K7: 20.58 | L7: 17.14 | M7: =IF(J7="Took",L7,ROUND(G7*(1+Assumptions!$B$14)-(C7+E7)*Assumptions!$B$13,2)) | N7: Take | O7: Take | P7: Take | Q7: Take | R7: Take | S7: 3026c5
A8: 46296.614 | B8: Uber | C8: 2.06 | D8: 7.3 | E8: 11.98 | F8: 29.7 | G8: 23.41 | H8: =IFERROR(G8/(C8+E8),0) | I8: =IFERROR((G8-(C8+E8)*Assumptions!$B$13)/((D8+F8)/60),0) | J8: Passed | M8: =IF(J8="Took",L8,ROUND(G8*(1+Assumptions!$B$14)-(C8+E8)*Assumptions!$B$13,2)) | N8: Busy | O8: Skip | P8: Busy | Q8: Busy | R8: Busy | S8: 9fc858
A9: 46296.625 | B9: Uber | C9: 1.75 | D9: 7.5 | E9: 8.65 | F9: 28.1 | G9: 8.9 | H9: =IFERROR(G9/(C9+E9),0) | I9: =IFERROR((G9-(C9+E9)*Assumptions!$B$13)/((D9+F9)/60),0) | J9: Took | K9: 8.9 | L9: 6.02 | M9: =IF(J9="Took",L9,ROUND(G9*(1+Assumptions!$B$14)-(C9+E9)*Assumptions!$B$13,2)) | N9: Take | O9: Take | P9: Skip | Q9: Skip | R9: Take | S9: ab2047
A10: 46296.738 | B10: Uber | C10: 3.08 | D10: 10 | E10: 5.61 | F10: 17 | G10: 11.8 | H10: =IFERROR(G10/(C10+E10),0) | I10: =IFERROR((G10-(C10+E10)*Assumptions!$B$13)/((D10+F10)/60),0) | J10: Passed | M10: =IF(J10="Took",L10,ROUND(G10*(1+Assumptions!$B$14)-(C10+E10)*Assumptions!$B$13,2)) | N10: Skip | O10: Skip | P10: Busy | Q10: Busy | R10: Busy | S10: a3a684
A11: 46296.749 | B11: Uber | C11: 0.37 | D11: 3.6 | E11: 8.69 | F11: 24.2 | G11: 17.79 | H11: =IFERROR(G11/(C11+E11),0) | I11: =IFERROR((G11-(C11+E11)*Assumptions!$B$13)/((D11+F11)/60),0) | J11: Took | K11: 23.19 | L11: 20.64 | M11: =IF(J11="Took",L11,ROUND(G11*(1+Assumptions!$B$14)-(C11+E11)*Assumptions!$B$13,2)) | N11: Take | O11: Take | P11: Take | Q11: Take | R11: Take | S11: 6b8bbd
A12: 46296.777 | B12: Uber | C12: 1.19 | D12: 5.1 | E12: 7.7 | F12: 23.4 | G12: 17.23 | H12: =IFERROR(G12/(C12+E12),0) | I12: =IFERROR((G12-(C12+E12)*Assumptions!$B$13)/((D12+F12)/60),0) | J12: Passed | M12: =IF(J12="Took",L12,ROUND(G12*(1+Assumptions!$B$14)-(C12+E12)*Assumptions!$B$13,2)) | N12: Busy | O12: Busy | P12: Busy | Q12: Busy | R12: Busy | S12: e2013e
A13: 46296.79 | B13: Uber | C13: 0.82 | D13: 5.1 | E13: 8.16 | F13: 26.6 | G13: 18.84 | H13: =IFERROR(G13/(C13+E13),0) | I13: =IFERROR((G13-(C13+E13)*Assumptions!$B$13)/((D13+F13)/60),0) | J13: Took | K13: 18.84 | L13: 16.35 | M13: =IF(J13="Took",L13,ROUND(G13*(1+Assumptions!$B$14)-(C13+E13)*Assumptions!$B$13,2)) | N13: Take | O13: Take | P13: Take | Q13: Take | R13: Take | S13: 114f2a
A14: 46297.266 | B14: Uber | C14: 3.99 | D14: 12.4 | E14: 13.19 | F14: 34 | G14: 23.73 | H14: =IFERROR(G14/(C14+E14),0) | I14: =IFERROR((G14-(C14+E14)*Assumptions!$B$13)/((D14+F14)/60),0) | J14: Passed | M14: =IF(J14="Took",L14,ROUND(G14*(1+Assumptions!$B$14)-(C14+E14)*Assumptions!$B$13,2)) | N14: Skip | O14: Skip | P14: Busy | Q14: Busy | R14: Busy | S14: 1bec76
A15: 46297.272 | B15: Uber | C15: 1.94 | D15: 7.5 | E15: 7.97 | F15: 23.8 | G15: 16.45 | H15: =IFERROR(G15/(C15+E15),0) | I15: =IFERROR((G15-(C15+E15)*Assumptions!$B$13)/((D15+F15)/60),0) | J15: Took | K15: 16.45 | L15: 13.67 | M15: =IF(J15="Took",L15,ROUND(G15*(1+Assumptions!$B$14)-(C15+E15)*Assumptions!$B$13,2)) | N15: Take | O15: Take | P15: Take | Q15: Take | R15: Take | S15: a620b2
A16: 46297.437 | B16: Lyft | C16: 4.52 | D16: 13.8 | E16: 17.45 | F16: 42.1 | G16: 30.42 | H16: =IFERROR(G16/(C16+E16),0) | I16: =IFERROR((G16-(C16+E16)*Assumptions!$B$13)/((D16+F16)/60),0) | J16: Passed | M16: =IF(J16="Took",L16,ROUND(G16*(1+Assumptions!$B$14)-(C16+E16)*Assumptions!$B$13,2)) | N16: Skip | O16: Skip | P16: Busy | Q16: Busy | R16: Busy | S16: 991f83
A17: 46297.44 | B17: Uber | C17: 1.41 | D17: 6.3 | E17: 8.06 | F17: 21.3 | G17: 27.12 | H17: =IFERROR(G17/(C17+E17),0) | I17: =IFERROR((G17-(C17+E17)*Assumptions!$B$13)/((D17+F17)/60),0) | J17: Took | K17: 27.12 | L17: 24.46 | M17: =IF(J17="Took",L17,ROUND(G17*(1+Assumptions!$B$14)-(C17+E17)*Assumptions!$B$13,2)) | N17: Take | O17: Take | P17: Take | Q17: Take | R17: Take | S17: 69493b
A18: 46297.501 | B18: Uber | C18: 5.73 | D18: 16.9 | E18: 14.74 | F18: 39.6 | G18: 28.3 | H18: =IFERROR(G18/(C18+E18),0) | I18: =IFERROR((G18-(C18+E18)*Assumptions!$B$13)/((D18+F18)/60),0) | J18: Passed | M18: =IF(J18="Took",L18,ROUND(G18*(1+Assumptions!$B$14)-(C18+E18)*Assumptions!$B$13,2)) | N18: Skip | O18: Skip | P18: Busy | Q18: Busy | R18: Busy | S18: 4ae5b9
A19: 46297.51 | B19: Uber | C19: 0.67 | D19: 3.5 | E19: 25.62 | F19: 60.5 | G19: 56.87 | H19: =IFERROR(G19/(C19+E19),0) | I19: =IFERROR((G19-(C19+E19)*Assumptions!$B$13)/((D19+F19)/60),0) | J19: Took | K19: 56.87 | L19: 49.46 | M19: =IF(J19="Took",L19,ROUND(G19*(1+Assumptions!$B$14)-(C19+E19)*Assumptions!$B$13,2)) | N19: Take | O19: Take | P19: Take | Q19: Take | R19: Take | S19: 28895a
A20: 46297.618 | B20: Uber | C20: 2.84 | D20: 9.4 | E20: 2.61 | F20: 10.3 | G20: 8.61 | H20: =IFERROR(G20/(C20+E20),0) | I20: =IFERROR((G20-(C20+E20)*Assumptions!$B$13)/((D20+F20)/60),0) | J20: Passed | M20: =IF(J20="Took",L20,ROUND(G20*(1+Assumptions!$B$14)-(C20+E20)*Assumptions!$B$13,2)) | N20: Busy | O20: Skip | P20: Busy | Q20: Busy | R20: Busy | S20: 57e76b
A21: 46297.622 | B21: Uber | C21: 1.55 | D21: 6.9 | E21: 7.39 | F21: 19.4 | G21: 22.7 | H21: =IFERROR(G21/(C21+E21),0) | I21: =IFERROR((G21-(C21+E21)*Assumptions!$B$13)/((D21+F21)/60),0) | J21: Took | K21: 22.7 | L21: 20.17 | M21: =IF(J21="Took",L21,ROUND(G21*(1+Assumptions!$B$14)-(C21+E21)*Assumptions!$B$13,2)) | N21: Take | O21: Take | P21: Take | Q21: Take | R21: Take | S21: 3b2f8f
A22: 46297.638 | B22: Uber | C22: 1.56 | D22: 6.4 | E22: 21.11 | F22: 55.9 | G22: 50.63 | H22: =IFERROR(G22/(C22+E22),0) | I22: =IFERROR((G22-(C22+E22)*Assumptions!$B$13)/((D22+F22)/60),0) | J22: Took | K22: 50.63 | L22: 44.3 | M22: =IF(J22="Took",L22,ROUND(G22*(1+Assumptions!$B$14)-(C22+E22)*Assumptions!$B$13,2)) | N22: Take | O22: Take | P22: Take | Q22: Take | R22: Take | S22: bb9e55
A23: 46297.639 | B23: Uber | C23: 3.01 | D23: 9.8 | E23: 16.45 | F23: 40.4 | G23: 31.12 | H23: =IFERROR(G23/(C23+E23),0) | I23: =IFERROR((G23-(C23+E23)*Assumptions!$B$13)/((D23+F23)/60),0) | J23: Passed | M23: =IF(J23="Took",L23,ROUND(G23*(1+Assumptions!$B$14)-(C23+E23)*Assumptions!$B$13,2)) | N23: Skip | O23: Skip | P23: Busy | Q23: Busy | R23: Busy | S23: 61be3f
A24: 46297.647 | B24: Uber | C24: 3.21 | D24: 11 | E24: 3.27 | F24: 16.4 | G24: 17.92 | H24: =IFERROR(G24/(C24+E24),0) | I24: =IFERROR((G24-(C24+E24)*Assumptions!$B$13)/((D24+F24)/60),0) | J24: Took | K24: 20.06 | L24: 18.25 | M24: =IF(J24="Took",L24,ROUND(G24*(1+Assumptions!$B$14)-(C24+E24)*Assumptions!$B$13,2)) | N24: Skip | O24: Skip | P24: Take | Q24: Take | R24: Take | S24: ce9bca
A25: 46297.868 | B25: Uber | C25: 1.1 | D25: 4.2 | E25: 7.6 | F25: 25.1 | G25: 11.2 | H25: =IFERROR(G25/(C25+E25),0) | I25: =IFERROR((G25-(C25+E25)*Assumptions!$B$13)/((D25+F25)/60),0) | J25: Took | K25: 11.2 | L25: 8.79 | M25: =IF(J25="Took",L25,ROUND(G25*(1+Assumptions!$B$14)-(C25+E25)*Assumptions!$B$13,2)) | N25: Take | O25: Take | P25: Take | Q25: Skip | R25: Take | S25: 474af1
A26: 46299.601 | B26: Uber | C26: 5.3 | D26: 15.8 | E26: 13.31 | F26: 33.6 | G26: 26.64 | H26: =IFERROR(G26/(C26+E26),0) | I26: =IFERROR((G26-(C26+E26)*Assumptions!$B$13)/((D26+F26)/60),0) | J26: Passed | M26: =IF(J26="Took",L26,ROUND(G26*(1+Assumptions!$B$14)-(C26+E26)*Assumptions!$B$13,2)) | N26: Skip | O26: Skip | P26: Take | Q26: Take | R26: Busy | S26: 6edf7e
A27: 46299.603 | B27: Lyft | C27: 3.54 | D27: 11.2 | E27: 14.25 | F27: 39.3 | G27: 26.64 | H27: =IFERROR(G27/(C27+E27),0) | I27: =IFERROR((G27-(C27+E27)*Assumptions!$B$13)/((D27+F27)/60),0) | J27: Passed | M27: =IF(J27="Took",L27,ROUND(G27*(1+Assumptions!$B$14)-(C27+E27)*Assumptions!$B$13,2)) | N27: Skip | O27: Skip | P27: Busy | Q27: Busy | R27: Busy | S27: ed4bd3
A28: 46299.607 | B28: Lyft | C28: 1.33 | D28: 4.8 | E28: 25.77 | F28: 61.4 | G28: 12.03 | H28: =IFERROR(G28/(C28+E28),0) | I28: =IFERROR((G28-(C28+E28)*Assumptions!$B$13)/((D28+F28)/60),0) | J28: Took | K28: 12.03 | L28: 4.51 | M28: =IF(J28="Took",L28,ROUND(G28*(1+Assumptions!$B$14)-(C28+E28)*Assumptions!$B$13,2)) | N28: Take | O28: Take | P28: Skip | Q28: Skip | R28: Take | S28: 09bfcb
A29: 46299.612 | B29: Uber | C29: 2.25 | D29: 7.7 | E29: 4.06 | F29: 16.7 | G29: 12.54 | H29: =IFERROR(G29/(C29+E29),0) | I29: =IFERROR((G29-(C29+E29)*Assumptions!$B$13)/((D29+F29)/60),0) | J29: Took | K29: 12.54 | L29: 10.78 | M29: =IF(J29="Took",L29,ROUND(G29*(1+Assumptions!$B$14)-(C29+E29)*Assumptions!$B$13,2)) | N29: Take | O29: Skip | P29: Take | Q29: Take | R29: Take | S29: f1df54
A30: 46299.619 | B30: Uber | C30: 1.76 | D30: 5.6 | E30: 25.75 | F30: 62.5 | G30: 56.8 | H30: =IFERROR(G30/(C30+E30),0) | I30: =IFERROR((G30-(C30+E30)*Assumptions!$B$13)/((D30+F30)/60),0) | J30: Took | K30: 56.8 | L30: 49.1 | M30: =IF(J30="Took",L30,ROUND(G30*(1+Assumptions!$B$14)-(C30+E30)*Assumptions!$B$13,2)) | N30: Take | O30: Take | P30: Take | Q30: Take | R30: Take | S30: 96bbc7
A31: 46299.677 | B31: Lyft | C31: 1.49 | D31: 5.9 | E31: 12.73 | F31: 32.9 | G31: 25.26 | H31: =IFERROR(G31/(C31+E31),0) | I31: =IFERROR((G31-(C31+E31)*Assumptions!$B$13)/((D31+F31)/60),0) | J31: Passed | M31: =IF(J31="Took",L31,ROUND(G31*(1+Assumptions!$B$14)-(C31+E31)*Assumptions!$B$13,2)) | N31: Busy | O31: Busy | P31: Busy | Q31: Busy | R31: Busy | S31: b1d3fc
A32: 46299.686 | B32: Uber | C32: 1.54 | D32: 6 | E32: 13.06 | F32: 32 | G32: 8.46 | H32: =IFERROR(G32/(C32+E32),0) | I32: =IFERROR((G32-(C32+E32)*Assumptions!$B$13)/((D32+F32)/60),0) | J32: Took | K32: 12.41 | L32: 8.35 | M32: =IF(J32="Took",L32,ROUND(G32*(1+Assumptions!$B$14)-(C32+E32)*Assumptions!$B$13,2)) | N32: Take | O32: Take | P32: Skip | Q32: Skip | R32: Take | S32: 4c7a57
A33: 46299.74 | B33: Uber | C33: 1.96 | D33: 7.1 | E33: 8.13 | F33: 21.4 | G33: 15.29 | H33: =IFERROR(G33/(C33+E33),0) | I33: =IFERROR((G33-(C33+E33)*Assumptions!$B$13)/((D33+F33)/60),0) | J33: Passed | M33: =IF(J33="Took",L33,ROUND(G33*(1+Assumptions!$B$14)-(C33+E33)*Assumptions!$B$13,2)) | N33: Busy | O33: Busy | P33: Busy | Q33: Busy | R33: Busy | S33: 25be7c
A34: 46299.743 | B34: Uber | C34: 1.98 | D34: 7.1 | E34: 24.41 | F34: 57 | G34: 42.45 | H34: =IFERROR(G34/(C34+E34),0) | I34: =IFERROR((G34-(C34+E34)*Assumptions!$B$13)/((D34+F34)/60),0) | J34: Passed | M34: =IF(J34="Took",L34,ROUND(G34*(1+Assumptions!$B$14)-(C34+E34)*Assumptions!$B$13,2)) | N34: Busy | O34: Busy | P34: Busy | Q34: Busy | R34: Busy | S34: e4f01b
A35: 46299.745 | B35: Uber | C35: 1.65 | D35: 6.7 | E35: 3.32 | F35: 15.3 | G35: 19.02 | H35: =IFERROR(G35/(C35+E35),0) | I35: =IFERROR((G35-(C35+E35)*Assumptions!$B$13)/((D35+F35)/60),0) | J35: Took | K35: 19.02 | L35: 17.64 | M35: =IF(J35="Took",L35,ROUND(G35*(1+Assumptions!$B$14)-(C35+E35)*Assumptions!$B$13,2)) | N35: Take | O35: Take | P35: Take | Q35: Take | R35: Take | S35: 7fb440
A36: 46299.751 | B36: Lyft | C36: 0.65 | D36: 3.4 | E36: 12.79 | F36: 31.6 | G36: 26.44 | H36: =IFERROR(G36/(C36+E36),0) | I36: =IFERROR((G36-(C36+E36)*Assumptions!$B$13)/((D36+F36)/60),0) | J36: Took | K36: 26.44 | L36: 22.67 | M36: =IF(J36="Took",L36,ROUND(G36*(1+Assumptions!$B$14)-(C36+E36)*Assumptions!$B$13,2)) | N36: Take | O36: Take | P36: Take | Q36: Take | R36: Take | S36: 13faf0
A37: 46299.818 | B37: Lyft | C37: 1.9 | D37: 6.9 | E37: 2.64 | F37: 8.9 | G37: 8.77 | H37: =IFERROR(G37/(C37+E37),0) | I37: =IFERROR((G37-(C37+E37)*Assumptions!$B$13)/((D37+F37)/60),0) | J37: Passed | M37: =IF(J37="Took",L37,ROUND(G37*(1+Assumptions!$B$14)-(C37+E37)*Assumptions!$B$13,2)) | N37: Take | O37: Take | P37: Take | Q37: Take | R37: Take | S37: 8274a4
A38: 46299.829 | B38: Uber | C38: 0.58 | D38: 3 | E38: 27.36 | F38: 66.1 | G38: 40.95 | H38: =IFERROR(G38/(C38+E38),0) | I38: =IFERROR((G38-(C38+E38)*Assumptions!$B$13)/((D38+F38)/60),0) | J38: Took | K38: 47.93 | L38: 40.11 | M38: =IF(J38="Took",L38,ROUND(G38*(1+Assumptions!$B$14)-(C38+E38)*Assumptions!$B$13,2)) | N38: Take | O38: Take | P38: Take | Q38: Take | R38: Take | S38: 57750f
A39: 46299.893 | B39: Uber | C39: 2.64 | D39: 8.9 | E39: 21.99 | F39: 56.3 | G39: 39.13 | H39: =IFERROR(G39/(C39+E39),0) | I39: =IFERROR((G39-(C39+E39)*Assumptions!$B$13)/((D39+F39)/60),0) | J39: Passed | M39: =IF(J39="Took",L39,ROUND(G39*(1+Assumptions!$B$14)-(C39+E39)*Assumptions!$B$13,2)) | N39: Busy | O39: Skip | P39: Busy | Q39: Busy | R39: Busy | S39: 88a939
A40: 46299.906 | B40: Uber | C40: 1.11 | D40: 4.3 | E40: 28.74 | F40: 67.2 | G40: 37.69 | H40: =IFERROR(G40/(C40+E40),0) | I40: =IFERROR((G40-(C40+E40)*Assumptions!$B$13)/((D40+F40)/60),0) | J40: Took | K40: 37.69 | L40: 29.41 | M40: =IF(J40="Took",L40,ROUND(G40*(1+Assumptions!$B$14)-(C40+E40)*Assumptions!$B$13,2)) | N40: Take | O40: Take | P40: Take | Q40: Take | R40: Take | S40: b2c30a
...
